Workbook

Sheet Summary
A1: Questbase QA sweep
A2: Build 5ed3f48
A3: Set Result on the Checklist sheet; these totals follow automatically.
A5: Overall | B5: Count
A6: Pass | B6: =COUNTIF(Checklist!$G$2:$G$120,"Pass")
A7: Fail | B7: =COUNTIF(Checklist!$G$2:$G$120,"Fail")
A8: Blocked | B8: =COUNTIF(Checklist!$G$2:$G$120,"Blocked")
A9: Not tested | B9: =COUNTIF(Checklist!$G$2:$G$120,"Not tested")
A10: N/A | B10: =COUNTIF(Checklist!$G$2:$G$120,"N/A")
A11: Total checks | B11: 119
A13: By section | B13: Pass | C13: Fail | D13: Blocked | E13: Not tested | F13: Total
A14: Before you start | B14: =COUNTIFS(Checklist!$B$2:$B$120,"Before you start",Checklist!$G$2:$G$120,"Pass") | C14: =COUNTIFS(Checklist!$B$2:$B$120,"Before you start",Checklist!$G$2:$G$120,"Fail") | D14: =COUNTIFS(Checklist!$B$2:$B$120,"Before you start",Checklist!$G$2:$G$120,"Blocked") | E14: =COUNTIFS(Checklist!$B$2:$B$120,"Before you start",Checklist!$G$2:$G$120,"Not tested") | F14: =COUNTIF(Checklist!$B$2:$B$120,"Before you start")
A15: Smoke — every route loads | B15: =COUNTIFS(Checklist!$B$2:$B$120,"Smoke — every route loads",Checklist!$G$2:$G$120,"Pass") | C15: =COUNTIFS(Checklist!$B$2:$B$120,"Smoke — every route loads",Checklist!$G$2:$G$120,"Fail") | D15: =COUNTIFS(Checklist!$B$2:$B$120,"Smoke — every route loads",Checklist!$G$2:$G$120,"Blocked") | E15: =COUNTIFS(Checklist!$B$2:$B$120,"Smoke — every route loads",Checklist!$G$2:$G$120,"Not tested") | F15: =COUNTIF(Checklist!$B$2:$B$120,"Smoke — every route loads")
A16: Shipped in the last two days | B16: =COUNTIFS(Checklist!$B$2:$B$120,"Shipped in the last two days",Checklist!$G$2:$G$120,"Pass") | C16: =COUNTIFS(Checklist!$B$2:$B$120,"Shipped in the last two days",Checklist!$G$2:$G$120,"Fail") | D16: =COUNTIFS(Checklist!$B$2:$B$120,"Shipped in the last two days",Checklist!$G$2:$G$120,"Blocked") | E16: =COUNTIFS(Checklist!$B$2:$B$120,"Shipped in the last two days",Checklist!$G$2:$G$120,"Not tested") | F16: =COUNTIF(Checklist!$B$2:$B$120,"Shipped in the last two days")
A17: Destructive and password-gated | B17: =COUNTIFS(Checklist!$B$2:$B$120,"Destructive and password-gated",Checklist!$G$2:$G$120,"Pass") | C17: =COUNTIFS(Checklist!$B$2:$B$120,"Destructive and password-gated",Checklist!$G$2:$G$120,"Fail") | D17: =COUNTIFS(Checklist!$B$2:$B$120,"Destructive and password-gated",Checklist!$G$2:$G$120,"Blocked") | E17: =COUNTIFS(Checklist!$B$2:$B$120,"Destructive and password-gated",Checklist!$G$2:$G$120,"Not tested") | F17: =COUNTIF(Checklist!$B$2:$B$120,"Destructive and password-gated")
A18: Quest CRM | B18: =COUNTIFS(Checklist!$B$2:$B$120,"Quest CRM",Checklist!$G$2:$G$120,"Pass") | C18: =COUNTIFS(Checklist!$B$2:$B$120,"Quest CRM",Checklist!$G$2:$G$120,"Fail") | D18: =COUNTIFS(Checklist!$B$2:$B$120,"Quest CRM",Checklist!$G$2:$G$120,"Blocked") | E18: =COUNTIFS(Checklist!$B$2:$B$120,"Quest CRM",Checklist!$G$2:$G$120,"Not tested") | F18: =COUNTIF(Checklist!$B$2:$B$120,"Quest CRM")
A19: Workspace and App Builder | B19: =COUNTIFS(Checklist!$B$2:$B$120,"Workspace and App Builder",Checklist!$G$2:$G$120,"Pass") | C19: =COUNTIFS(Checklist!$B$2:$B$120,"Workspace and App Builder",Checklist!$G$2:$G$120,"Fail") | D19: =COUNTIFS(Checklist!$B$2:$B$120,"Workspace and App Builder",Checklist!$G$2:$G$120,"Blocked") | E19: =COUNTIFS(Checklist!$B$2:$B$120,"Workspace and App Builder",Checklist!$G$2:$G$120,"Not tested") | F19: =COUNTIF(Checklist!$B$2:$B$120,"Workspace and App Builder")
A20: Operations, finance and estimating | B20: =COUNTIFS(Checklist!$B$2:$B$120,"Operations, finance and estimating",Checklist!$G$2:$G$120,"Pass") | C20: =COUNTIFS(Checklist!$B$2:$B$120,"Operations, finance and estimating",Checklist!$G$2:$G$120,"Fail") | D20: =COUNTIFS(Checklist!$B$2:$B$120,"Operations, finance and estimating",Checklist!$G$2:$G$120,"Blocked") | E20: =COUNTIFS(Checklist!$B$2:$B$120,"Operations, finance and estimating",Checklist!$G$2:$G$120,"Not tested") | F20: =COUNTIF(Checklist!$B$2:$B$120,"Operations, finance and estimating")
A21: Messages, notifications and search | B21: =COUNTIFS(Checklist!$B$2:$B$120,"Messages, notifications and search",Checklist!$G$2:$G$120,"Pass") | C21: =COUNTIFS(Checklist!$B$2:$B$120,"Messages, notifications and search",Checklist!$G$2:$G$120,"Fail") | D21: =COUNTIFS(Checklist!$B$2:$B$120,"Messages, notifications and search",Checklist!$G$2:$G$120,"Blocked") | E21: =COUNTIFS(Checklist!$B$2:$B$120,"Messages, notifications and search",Checklist!$G$2:$G$120,"Not tested") | F21: =COUNTIF(Checklist!$B$2:$B$120,"Messages, notifications and search")
A22: Company, users and platform | B22: =COUNTIFS(Checklist!$B$2:$B$120,"Company, users and platform",Checklist!$G$2:$G$120,"Pass") | C22: =COUNTIFS(Checklist!$B$2:$B$120,"Company, users and platform",Checklist!$G$2:$G$120,"Fail") | D22: =COUNTIFS(Checklist!$B$2:$B$120,"Company, users and platform",Checklist!$G$2:$G$120,"Blocked") | E22: =COUNTIFS(Checklist!$B$2:$B$120,"Company, users and platform",Checklist!$G$2:$G$120,"Not tested") | F22: =COUNTIF(Checklist!$B$2:$B$120,"Company, users and platform")
A23: Cross-cutting | B23: =COUNTIFS(Checklist!$B$2:$B$120,"Cross-cutting",Checklist!$G$2:$G$120,"Pass") | C23: =COUNTIFS(Checklist!$B$2:$B$120,"Cross-cutting",Checklist!$G$2:$G$120,"Fail") | D23: =COUNTIFS(Checklist!$B$2:$B$120,"Cross-cutting",Checklist!$G$2:$G$120,"Blocked") | E23: =COUNTIFS(Checklist!$B$2:$B$120,"Cross-cutting",Checklist!$G$2:$G$120,"Not tested") | F23: =COUNTIF(Checklist!$B$2:$B$120,"Cross-cutting")
A24: Known issues — do not report these | B24: =COUNTIFS(Checklist!$B$2:$B$120,"Known issues — do not report these",Checklist!$G$2:$G$120,"Pass") | C24: =COUNTIFS(Checklist!$B$2:$B$120,"Known issues — do not report these",Checklist!$G$2:$G$120,"Fail") | D24: =COUNTIFS(Checklist!$B$2:$B$120,"Known issues — do not report these",Checklist!$G$2:$G$120,"Blocked") | E24: =COUNTIFS(Checklist!$B$2:$B$120,"Known issues — do not report these",Checklist!$G$2:$G$120,"Not tested") | F24: =COUNTIF(Checklist!$B$2:$B$120,"Known issues — do not report these")
A26: Critical checks outstanding | B26: =COUNTIFS(Checklist!$F$2:$F$120,"*critical*",Checklist!$G$2:$G$120,"Not tested")

Sheet Checklist
A1: ID | B1: Section | C1: Priority | D1: Check | E1: How to test / what to expect | F1: Flags | G1: Result | H1: Tester | I1: Date | J1: Notes
A2: PREP-01 | B2: Before you start | C2: Start | D2: Confirm the build under test | E2: Open the app and check the build id in the sidebar header. It should read 5ed3f48 or later. An older build means you are testing yesterday's bugs. | G2: Not tested
A3: PREP-02 | B3: Before you start | C3: Start | D3: Have two accounts ready | E3: An owner account and a limited-role member in the same company. Permission gates cannot be tested from an owner account — everything passes. | F3: blocks permissions | G3: Not tested
A4: PREP-03 | B4: Before you start | C4: Start | D4: Open the browser console and leave it open | E4: A red error in the console is a fail even when the screen looks right. Note the first error, not the tenth — later ones are usually consequences. | G4: Not tested
A5: PREP-04 | B5: Before you start | C5: Start | D5: Decide what a fail means | E5: Fail = wrong result, lost data, a dead control, or a console error. Not a fail: anything in the Known issues section at the bottom. | G5: Not tested
A6: SMOKE-01 | B6: Smoke — every route loads | C6: P0 | D6: /dashboard | E6: Loads, shows content (not an empty shell or a stuck loader), no console error. | G6: Not tested
A7: SMOKE-02 | B7: Smoke — every route loads | C7: P0 | D7: /workday | E7: Loads, shows content (not an empty shell or a stuck loader), no console error. | G7: Not tested
A8: SMOKE-03 | B8: Smoke — every route loads | C8: P0 | D8: /jobs | E8: Loads, shows content (not an empty shell or a stuck loader), no console error. | G8: Not tested
A9: SMOKE-04 | B9: Smoke — every route loads | C9: P0 | D9: /tasks | E9: Loads, shows content (not an empty shell or a stuck loader), no console error. | G9: Not tested
A10: SMOKE-05 | B10: Smoke — every route loads | C10: P0 | D10: /files | E10: Loads, shows content (not an empty shell or a stuck loader), no console error. | G10: Not tested
A11: SMOKE-06 | B11: Smoke — every route loads | C11: P0 | D11: /client-portals | E11: Loads, shows content (not an empty shell or a stuck loader), no console error. | G11: Not tested
A12: SMOKE-07 | B12: Smoke — every route loads | C12: P0 | D12: /workspaces | E12: Loads, shows content (not an empty shell or a stuck loader), no console error. | G12: Not tested
A13: SMOKE-08 | B13: Smoke — every route loads | C13: P0 | D13: /forms | E13: Loads, shows content (not an empty shell or a stuck loader), no console error. | G13: Not tested
A14: SMOKE-09 | B14: Smoke — every route loads | C14: P0 | D14: /analytics | E14: Loads, shows content (not an empty shell or a stuck loader), no console error. | G14: Not tested
A15: SMOKE-10 | B15: Smoke — every route loads | C15: P0 | D15: /crm | E15: Loads, shows content (not an empty shell or a stuck loader), no console error. | G15: Not tested
... A26: SMOKE-21 | B26: Smoke — every route loads | C26: P0 | D26: /team-chart | E26: Loads, shows content (not an empty shell or a stuck loader), no console error. | G26: Not tested
A27: NEW-01 | B27: Shipped in the last two days | C27: P1 | D27: Job saves with no client | E27: Add job → fill only the name → Save. Expect: it saves. This failed on a foreign key before; if it errors again, stop and report immediately. | F27: critical, new, was broken | G27: Not tested
A28: NEW-02 | B28: Shipped in the last two days | C28: P1 | D28: Clear activity log — wrong password refused | E28: Configure workspace → Clear log → enter a wrong password → Clear. Expect: "Incorrect password", log untouched. | F28: critical, new, destructive | G28: Not tested
A29: NEW-03 | B29: Shipped in the last two days | C29: P1 | D29: Clear activity log — correct password works | E29: Repeat with the right password. Expect: log cleared, exactly one entry left saying who cleared it and how many went. | F29: critical, new, destructive | G29: Not tested
A30: NEW-04 | B30: Shipped in the last two days | C30: P1 | D30: Clearing the log leaves the feed alone | E30: After clearing, check the workspace Activity feed. Expect: posts, files and links are all still there. Only the action log is cleared. | G30: Not tested
A31: NEW-05 | B31: Shipped in the last two days | C31: P1 | D31: The password field is typeable | E31: Click into the password box and type. Expect: characters appear in it. Previously keystrokes were stolen by the command palette. | F31: was broken | G31: Not tested
A32: NEW-06 | B32: Shipped in the last two days | C32: P1 | D32: Configure workspace header | E32: Expect: Clear log, Save workspace and Close along the top; no Cancel button at the bottom. | F32: new | G32: Not tested
A33: NEW-07 | B33: Shipped in the last two days | C33: P1 | D33: Enter still saves | E33: In Configure workspace, put the cursor in the name field and press Enter. Expect: it saves, same as clicking Save. | G33: Not tested
A34: NEW-08 | B34: Shipped in the last two days | C34: P1 | D34: Saving a workspace stays put | E34: Rename a workspace from the sidebar gear while on the Activity page. Expect: you stay on Activity. It used to throw you to Settings. | F34: was broken | G34: Not tested
A35: NEW-09 | B35: Shipped in the last two days | C35: P1 | D35: Activity log shows date and time | E35: Expect: each entry reads like "Aug 3, 2026 · 10:52 AM" followed by the relative time. | F35: new | G35: Not tested
A36: NEW-10 | B36: Shipped in the last two days | C36: P1 | D36: Select one job and delete it | E36: Jobs → List → tick one row → Delete 1. Expect: password prompt, then it goes to the Recycle Bin. | F36: critical, new, destructive | G36: Not tested
A37: NEW-11 | B37: Shipped in the last two days | C37: P1 | D37: Select several jobs and delete them | E37: Tick three → Delete 3. Expect: a progress bar counting "1 of 3", "2 of 3", then all three in the Recycle Bin. | F37: critical, new, destructive | G37: Not tested
A38: NEW-12 | B38: Shipped in the last two days | C38: P1 | D38: Deleted jobs restore | E38: Recycle Bin → restore them. Expect: they return to the Jobs list intact. | F38: critical | G38: Not tested
A39: NEW-13 | B39: Shipped in the last two days | C39: P1 | D39: Select-all respects the filter | E39: Filter the Jobs list, tick select-all, clear the filter. Expect: only the filtered rows are ticked. | G39: Not tested
A40: NEW-14 | B40: Shipped in the last two days | C40: P1 | D40: Ticking a row does not open the job | E40: Click a row's checkbox. Expect: it ticks and you stay on the list. | G40: Not tested
A41: NEW-15 | B41: Shipped in the last two days | C41: P1 | D41: Bulk delete is hidden from a limited role | E41: As the limited account, select jobs. Expect: no Delete button. | F41: critical, permissions | G41: Not tested
A42: NEW-16 | B42: Shipped in the last two days | C42: P1 | D42: Only one scrollbar | E42: On the dashboard and workspaces pages. Expect: one scrollbar on the content, none on the window. | F42: was broken | G42: Not tested
A43: NEW-17 | B43: Shipped in the last two days | C43: P1 | D43: App strip drag | E43: Workspaces → hold left button on the app strip and drag. Expect: it pans and glides to a stop; a click still opens an app. | G43: Not tested
A44: NEW-18 | B44: Shipped in the last two days | C44: P1 | D44: App strip keeps its place | E44: Scroll the app strip sideways, then click an app. Expect: the strip stays where you left it. | G44: Not tested
A45: NEW-19 | B45: Shipped in the last two days | C45: P1 | D45: Command palette over a dialog | E45: Open any dialog, press Ctrl+K. Expect: the palette does not open over it. | F45: was broken | G45: Not tested
A46: NEW-20 | B46: Shipped in the last two days | C46: P1 | D46: Sidebar themes and icon packs | E46: Settings → Appearance → try each sidebar theme and icon pack. Expect: icons all render (no blank squares), text stays readable on every theme. | F46: new | G46: Not tested
A47: NEW-21 | B47: Shipped in the last two days | C47: P1 | D47: Appearance is per-account | E47: Change your sidebar theme, then check the limited account. Expect: their appearance is unchanged. | G47: Not tested
A48: DEL-01 | B48: Destructive and password-gated | C48: P1 | D48: Recycle-bin deletes across records | E48: Delete one of each: contact, job, quote, task, file, form, client portal, knowledge article. Expect: each confirms first, then appears in the Recycle Bin. | F48: critical | G48: Not tested
A49: DEL-02 | B49: Destructive and password-gated | C49: P1 | D49: Restore from the Recycle Bin | E49: Restore each one. Expect: the record comes back where it was, with its fields intact. | F49: critical | G49: Not tested
A50: DEL-03 | B50: Destructive and password-gated | C50: P1 | D50: Undo immediately after deleting | E50: Delete a record and use the undo on the toast. Expect: it comes straight back. | F50: undo-recycle-delete | G50: Not tested
...

Sheet Coverage
A1: Module | B1: Clickable actions
A2: Forms (build, publish, responses) | B2: 40
A3: Workspaces / App Builder | B3: 36
A4: Client portals | B4: 34
A5: Contacts | B5: 33
A6: Messages | B6: 23
A7: Dashboard | B7: 17
A8: Files / Drive | B8: 16
A9: Jobs | B9: 15
A10: Price Book | B10: 13
A11: Settings / Appearance | B11: 13
A12: Users, roles, invites | B12: 11
A13: Quotes | B13: 9
... A25: Total distinct actions | B25: 364
A27: Counted from the source: distinct data-action handlers per module. The checklist covers each module’s core loop rather than all 364 individually; destructive paths are listed in full.
