Workbook

Sheet Checks
A1: ID | B1: Area | C1: Section | D1: Check | E1: Expected result | F1: Flag | G1: Status | H1: Tester | I1: Date | J1: Notes / defect
A2: WS-01 | B2: Workspace app | C2: Rail and switching | D2: Switching workspace lands on its apps. | E2: From Settings (or any section but Apps), pick another workspace in the rail. The new workspace's app list opens with no app pre-selected — not the same admin screen under a different subject. | F2: NEW | G2: Not run
A3: WS-02 | B3: Workspace app | C3: Rail and switching | D3: A role without workspaces.view is not dumped on Apps. | E3: As a member whose role cannot open Apps, switch workspace. They stay on the section they were on rather than landing on a page that refuses them. | F3: NEW | G3: Not run
A4: WS-03 | B4: Workspace app | C4: Rail and switching | D4: Rail order drags and persists company-wide. | E4: Drag a workspace up the rail, reload, then check from a second account in the same company. Same order. The default workspace is no longer pinned first and can be moved. | G4: Not run
A5: WS-04 | B5: Workspace app | C5: Rail and switching | D5: Reorder is company-admin only. | E5: A non-admin cannot drag the rail, and the whole order is sent on every move — no partial reconciliation. | G5: Not run
A6: WS-05 | B6: Workspace app | C6: Rail and switching | D6: A stale workspace or company in the URL reconciles before render. | E6: Paste a URL for a workspace you cannot enter. You land on an allowed tenant; the URL and what is on screen agree. | G6: Not run
A7: WS-06 | B7: Workspace app | C7: Workspace home | D7: One of each tile type renders and survives a reload. | E7: Apps, App, Report, Tasks, Members, Calendar, Contacts, Jobs, Text, Image, Links, Clock — all twelve, plus reorder and resize. | G7: Not run
A8: WS-07 | B8: Workspace app | C8: Workspace home | D8: The Jobs tile's parts tick on and off. | E8: Working today, Draws ready, Spent to date, Production health and the draws list. An untouched tile shows the useful default set; ticking everything off gives a blank tile, not a crash. | G8: Not run
A9: WS-08 | B9: Workspace app | C9: Workspace home | D9: A running clock ticks in seconds and steals no focus. | E9: Start a timer, then type into a field on the same page. The rail clock and the Clock tile tick every second; the caret never moves and nothing is re-rendered. 10:38:47 PM fits inside the tile. | F9: REGRESSION | G9: Not run
A10: WS-09 | B10: Workspace app | C10: Workspace home | D10: The activity feed and the tile column scroll separately above 900px. | E10: Each column has its own scrollbar and equal height. Reaching the end of the tiles does not mean scrolling past the whole feed, and neither column grows a horizontal bar. | F10: REGRESSION | G10: Not run
A11: WS-10 | B11: Workspace app | C11: Workspace home | D11: Below 900px they stack and the page takes its scroll back. | E11: One scrollport on a phone. No nested scrolling trap. | G11: Not run
A12: WS-11 | B12: Workspace app | C12: Workspace home | D12: Clearing the activity log leaves a trace. | E12: One entry survives naming who cleared it and how many went. Feed posts, company audit events and per-record history are all untouched. | G12: Not run
A13: WS-12 | B13: Workspace app | C13: App shell and tabs | D13: The tab strip stays put while the app list scrolls under it. | E13: Open an app with more records than fit. The strip is sticky against the top of the surface, the list scrolls inside itself with overscroll contained, and the strip sits below menus rather than over them. | F13: NEW | G13: Not run
A14: WS-13 | B14: Workspace app | C14: App shell and tabs | D14: App tiles in the topbar wrap between words only. | E14: "Underwriter" does not break as "Underwrite / r". A name too long for two lines is clipped with an ellipsis, not cut mid-word. | F14: REGRESSION | G14: Not run
A15: WS-14 | B15: Workspace app | C15: App shell and tabs | D15: Per-app tab visibility. | E15: Turn Reports off in the app's Settings — it leaves the strip, and a bookmarked ?tab=reports falls through to a tab that does exist. | G15: Not run
A16: WS-15 | B16: Workspace app | C16: App shell and tabs | D16: All five item layouts render. | E16: Table, Cards, Board, Badges, Activity. A record's card is identical in Cards and on the Board. | G16: Not run
A17: WS-16 | B17: Workspace app | C17: App shell and tabs | D17: Dragging a card between board columns writes the status field. | E17: The column count, the saved-view count and the stage card all agree afterwards — they are one function. | G17: Not run
A18: WS-17 | B18: Workspace app | C18: App shell and tabs | D18: Every stage the rail offers is clickable. | E18: Click each stage in turn on a Deals and a Jobs record. None silently snaps back to the first stage; an unrecognised stage is kept and shown, not rewritten. | F18: REGRESSION | G18: Not run
A19: WS-18 | B19: Workspace app | C19: App shell and tabs | D19: Default sort is newest first. | E19: A record with no created stamp orders by its updated stamp instead of sinking to the bottom. | G19: Not run
A20: WS-19 | B20: Workspace app | C20: App shell and tabs | D20: Stage nav and chip filters combine, and counts survive filtering. | G20: Not run
A21: WS-20 | B21: Workspace app | C21: App shell and tabs | D21: Saved views: team versus private. | E21: A team view appears for a second account; a private view does not, and is gone in a different browser. Only status and category fields are offered as the split. | G21: Not run
A22: WS-21 | B22: Workspace app | C22: App shell and tabs | D22: Calendar month, week and day — including sub-item dates. | E22: An app whose dates live on its Dailies puts them on the calendar as "Dailies · Date", and clicking one opens the parent record. | G22: Not run
A23: WS-22 | B23: Workspace app | C23: App shell and tabs | D23: Reports tab and its print view show the same figures. | E23: KPI tiles, donut, bar and sparkline. Print opens in the same click, not blocked as a pop-up. | G23: Not run
A24: WS-23 | B24: Workspace app | C24: Records and live state | D24: A long record panel scrolls inside itself. | E24: Open a record with a long Activity and Comments thread. The panel caps at the viewport, the header stays put, and one scrollbar governs the conversation — not two. | F24: NEW | G24: Not run
A25: WS-24 | B25: Workspace app | C25: Records and live state | D25: Below 900px the record panels scroll with the page again. | F25: NEW | G25: Not run
A26: WS-25 | B26: Workspace app | C26: Records and live state | D26: Activity and Comments are two different things. | E26: Activity shows created, field changes, checklist ticks, sheet edits, automation runs and the latest comments. Comments shows comments only. | G26: Not run
A27: WS-26 | B27: Workspace app | C27: Records and live state | D27: A mention notifies the person named, and the sound plays once. | G27: Not run
A28: WS-27 | B28: Workspace app | C28: Records and live state | D28: A presence change never repaints over somebody typing. | E28: Type into a record while a second account signs in. Nothing is re-rendered and no keystroke is lost; the online ring appears about a second and a half after you stop. | F28: NEW | G28: Not run
A29: WS-28 | B29: Workspace app | C29: Records and live state | D29: Recycle bin: delete, restore, purge. | E29: A deleted record lands in Trash stamped with who and when, restores with every value intact, and purge is final. Records older than 30 days are the ones offered for clearing. | G29: Not run
A30: WS-29 | B30: Workspace app | C30: Records and live state | D30: CSV export and import round-trip. | E30: Quoted commas, quotes and newlines survive; an empty column stays a column; option labels export as labels, not ids. | G30: Not run
A31: WS-30 | B31: Workspace app | C31: Records and live state | D31: Download an app and install it into another workspace. | E31: Field ids are reminted, and the record layout, card fields, sub-item lists, dashboard and saved views all still point at real fields — not an empty card. | G31: Not run
A32: AB-01 | B32: Workspace App Builder | C32: The app and its field list | D32: Create an app: name, icon, colour. | E32: A custom colour is accepted only as a CSS hex; an imported app carrying anything else is constrained before it reaches a style attribute. | G32: Not run
A33: AB-02 | B33: Workspace App Builder | C33: The app and its field list | D33: The palette search filters the type list. | E33: Type "but" into Search field types: only Button is left, and the search box itself stays on screen — it sits in the palette head, outside what is being filtered. | F33: NEW | G33: Not run
A34: AB-03 | B34: Workspace App Builder | C34: The app and its field list | D34: Dragging a type from the palette onto the empty field list adds it. | E34: Not only onto an existing row. Both drop targets work in an app and in the Company Contacts editor. | F34: REGRESSION | G34: Not run
A35: AB-04 | B35: Workspace App Builder | C35: The app and its field list | D35: Drag-to-reorder renumbers from what is on screen. | G35: Not run
A36: AB-05 | B36: Workspace App Builder | C36: The app and its field list | D36: The eye hides a field from the items table only. | E36: Still on the record, still on the form, still stored. | G36: Not run
A37: AB-06 | B37: Workspace App Builder | C37: The app and its field list | D37: Deleting a field warns first, and a new field of the same name does not inherit the old values. | G37: Not run
A38: AB-07 | B38: Workspace App Builder | C38: The app and its field list | D38: Without workspaces.manage there is no palette and no row actions. | E38: The Fields tab is readable, not editable. Verify as a Member, not as an Owner — an Owner holds every permission by rank and cannot see this. | G38: Not run
A39: AB-08 | B39: Workspace App Builder | C39: The app and its field list | D39: Record wording follows the app name. | E39: "Add job", not "Add item". Companies → Company, Properties → Property; a name the singulariser cannot handle is left whole rather than guessed at. | G39: Not run
A40: AB-09 | B40: Workspace App Builder | C40: Sub-item lists, automations, dashboard | D40: A sub-item list holds records inside a record. | E40: Add "Dailies" with its own fields and its own singular label; add several to one record; they survive a reload and appear on the calendar. | G40: Not run
...

Sheet Summary
A1: Questbase QA pass — where it stands
A2: Counts recalculate from the Checks sheet. Set each row’s Status there.
A4: Area | B4: Checks | C4: Pass | D4: Fail | E4: Blocked | F4: Not run | G4: New | H4: Regression
A5: Workspace app | B5: =COUNTIF(Checks!$B$2:$B$140,$A5) | C5: =COUNTIFS(Checks!$B$2:$B$140,$A5,Checks!$G$2:$G$140,"Pass") | D5: =COUNTIFS(Checks!$B$2:$B$140,$A5,Checks!$G$2:$G$140,"Fail") | E5: =COUNTIFS(Checks!$B$2:$B$140,$A5,Checks!$G$2:$G$140,"Blocked") | F5: =COUNTIFS(Checks!$B$2:$B$140,$A5,Checks!$G$2:$G$140,"Not run") | G5: =COUNTIFS(Checks!$B$2:$B$140,$A5,Checks!$F$2:$F$140,"NEW") | H5: =COUNTIFS(Checks!$B$2:$B$140,$A5,Checks!$F$2:$F$140,"REGRESSION")
A6: Workspace App Builder | B6: =COUNTIF(Checks!$B$2:$B$140,$A6) | C6: =COUNTIFS(Checks!$B$2:$B$140,$A6,Checks!$G$2:$G$140,"Pass") | D6: =COUNTIFS(Checks!$B$2:$B$140,$A6,Checks!$G$2:$G$140,"Fail") | E6: =COUNTIFS(Checks!$B$2:$B$140,$A6,Checks!$G$2:$G$140,"Blocked") | F6: =COUNTIFS(Checks!$B$2:$B$140,$A6,Checks!$G$2:$G$140,"Not run") | G6: =COUNTIFS(Checks!$B$2:$B$140,$A6,Checks!$F$2:$F$140,"NEW") | H6: =COUNTIFS(Checks!$B$2:$B$140,$A6,Checks!$F$2:$F$140,"REGRESSION")
A7: App fields | B7: =COUNTIF(Checks!$B$2:$B$140,$A7) | C7: =COUNTIFS(Checks!$B$2:$B$140,$A7,Checks!$G$2:$G$140,"Pass") | D7: =COUNTIFS(Checks!$B$2:$B$140,$A7,Checks!$G$2:$G$140,"Fail") | E7: =COUNTIFS(Checks!$B$2:$B$140,$A7,Checks!$G$2:$G$140,"Blocked") | F7: =COUNTIFS(Checks!$B$2:$B$140,$A7,Checks!$G$2:$G$140,"Not run") | G7: =COUNTIFS(Checks!$B$2:$B$140,$A7,Checks!$F$2:$F$140,"NEW") | H7: =COUNTIFS(Checks!$B$2:$B$140,$A7,Checks!$F$2:$F$140,"REGRESSION")
A8: Company Contacts | B8: =COUNTIF(Checks!$B$2:$B$140,$A8) | C8: =COUNTIFS(Checks!$B$2:$B$140,$A8,Checks!$G$2:$G$140,"Pass") | D8: =COUNTIFS(Checks!$B$2:$B$140,$A8,Checks!$G$2:$G$140,"Fail") | E8: =COUNTIFS(Checks!$B$2:$B$140,$A8,Checks!$G$2:$G$140,"Blocked") | F8: =COUNTIFS(Checks!$B$2:$B$140,$A8,Checks!$G$2:$G$140,"Not run") | G8: =COUNTIFS(Checks!$B$2:$B$140,$A8,Checks!$F$2:$F$140,"NEW") | H8: =COUNTIFS(Checks!$B$2:$B$140,$A8,Checks!$F$2:$F$140,"REGRESSION")
A9: Contact card | B9: =COUNTIF(Checks!$B$2:$B$140,$A9) | C9: =COUNTIFS(Checks!$B$2:$B$140,$A9,Checks!$G$2:$G$140,"Pass") | D9: =COUNTIFS(Checks!$B$2:$B$140,$A9,Checks!$G$2:$G$140,"Fail") | E9: =COUNTIFS(Checks!$B$2:$B$140,$A9,Checks!$G$2:$G$140,"Blocked") | F9: =COUNTIFS(Checks!$B$2:$B$140,$A9,Checks!$G$2:$G$140,"Not run") | G9: =COUNTIFS(Checks!$B$2:$B$140,$A9,Checks!$F$2:$F$140,"NEW") | H9: =COUNTIFS(Checks!$B$2:$B$140,$A9,Checks!$F$2:$F$140,"REGRESSION")
A10: All areas | B10: =SUM(B5:B9) | C10: =SUM(C5:C9) | D10: =SUM(D5:D9) | E10: =SUM(E5:E9) | F10: =SUM(F5:F9) | G10: =SUM(G5:G9) | H10: =SUM(H5:H9)
A12: Sign-off gate
A13: Every check has a status other than "Not run" | B13: =IF(COUNTIF(Checks!$G$2:$G$140,"Not run")=0,"Met","Outstanding: "&COUNTIF(Checks!$G$2:$G$140,"Not run"))
A14: No failures outstanding | B14: =IF(COUNTIF(Checks!$G$2:$G$140,"Fail")=0,"Met","Failures: "&COUNTIF(Checks!$G$2:$G$140,"Fail"))
A15: Every NEW check has been run | B15: =IF(COUNTIFS(Checks!$F$2:$F$140,"NEW",Checks!$G$2:$G$140,"Not run")=0,"Met","Outstanding: "&COUNTIFS(Checks!$F$2:$F$140,"NEW",Checks!$G$2:$G$140,"Not run"))
A16: npm test / ai:check / build / check all green | B16: No
A17: Verified in a browser, not only in the suite | B17: No

Sheet Reference
A1: Running the pass
A2: Run the areas in the order they appear on the Checks sheet — each one leaves behind what the next needs.
A4: Run these, in this order
A5: npm test — the full suite. A green run proves nothing about a function nothing calls; the Sheet editor shipped broken with 2,973 tests passing.
A6: npm run ai:check — project-brain validation.
A7: npm run build, then npm run check — including the bundle-budget gate. The 64-byte gzip tolerance is for CI-versus-local zlib differences, not spendable on a feature.
A8: Open the built bundle in a browser before believing any of it. Four bugs this month passed a source-text assertion that matched the broken line.
A10: Not bugs — do not raise these
A11: SMS is fail-closed by design; the workspace routing contract is not built.
A12: The formula grammar has no conditionals and no date arithmetic — "must total 100%" is shown, never enforced.
A13: A location field stores the address only; there is nowhere on a workspace field for coordinates.
A14: Calendar memo alarms fire only while a tab is open — no service worker, no push.
... A22: Contacts and the card — src/company-contacts/: page.js, model.js, timeline.js
